Watching for file changes with StatReloader
Exception in thread django-main-thread:
Traceback (most recent call last):
  File "/Library/Developer/CommandLineTools/Library/Frameworks/Python3.framework/Versions/3.9/lib/python3.9/threading.py", line 973, in _bootstrap_inner
    self.run()
  File "/Library/Developer/CommandLineTools/Library/Frameworks/Python3.framework/Versions/3.9/lib/python3.9/threading.py", line 910, in run
    self._target(*self._args, **self._kwargs)
  File "/Users/rafaelgarcia/Desktop/GitHub/data-alchemy-suite/.venv/lib/python3.9/site-packages/django/utils/autoreload.py", line 64, in wrapper
    fn(*args, **kwargs)
  File "/Users/rafaelgarcia/Desktop/GitHub/data-alchemy-suite/.venv/lib/python3.9/site-packages/django/core/management/commands/runserver.py", line 133, in inner_run
    self.check(display_num_errors=True)
  File "/Users/rafaelgarcia/Desktop/GitHub/data-alchemy-suite/.venv/lib/python3.9/site-packages/django/core/management/base.py", line 485, in check
    all_issues = checks.run_checks(
  File "/Users/rafaelgarcia/Desktop/GitHub/data-alchemy-suite/.venv/lib/python3.9/site-packages/django/core/checks/registry.py", line 88, in run_checks
    new_errors = check(app_configs=app_configs, databases=databases)
  File "/Users/rafaelgarcia/Desktop/GitHub/data-alchemy-suite/.venv/lib/python3.9/site-packages/django/core/checks/urls.py", line 14, in check_url_config
    return check_resolver(resolver)
  File "/Users/rafaelgarcia/Desktop/GitHub/data-alchemy-suite/.venv/lib/python3.9/site-packages/django/core/checks/urls.py", line 24, in check_resolver
    return check_method()
  File "/Users/rafaelgarcia/Desktop/GitHub/data-alchemy-suite/.venv/lib/python3.9/site-packages/django/urls/resolvers.py", line 494, in check
    for pattern in self.url_patterns:
  File "/Users/rafaelgarcia/Desktop/GitHub/data-alchemy-suite/.venv/lib/python3.9/site-packages/django/utils/functional.py", line 57, in __get__
    res = instance.__dict__[self.name] = self.func(instance)
  File "/Users/rafaelgarcia/Desktop/GitHub/data-alchemy-suite/.venv/lib/python3.9/site-packages/django/urls/resolvers.py", line 715, in url_patterns
    patterns = getattr(self.urlconf_module, "urlpatterns", self.urlconf_module)
  File "/Users/rafaelgarcia/Desktop/GitHub/data-alchemy-suite/.venv/lib/python3.9/site-packages/django/utils/functional.py", line 57, in __get__
    res = instance.__dict__[self.name] = self.func(instance)
  File "/Users/rafaelgarcia/Desktop/GitHub/data-alchemy-suite/.venv/lib/python3.9/site-packages/django/urls/resolvers.py", line 708, in urlconf_module
    return import_module(self.urlconf_name)
  File "/Library/Developer/CommandLineTools/Library/Frameworks/Python3.framework/Versions/3.9/lib/python3.9/importlib/__init__.py", line 127, in import_module
    return _bootstrap._gcd_import(name[level:], package, level)
  File "<frozen importlib._bootstrap>", line 1030, in _gcd_import
  File "<frozen importlib._bootstrap>", line 1007, in _find_and_load
  File "<frozen importlib._bootstrap>", line 986, in _find_and_load_unlocked
  File "<frozen importlib._bootstrap>", line 680, in _load_unlocked
  File "<frozen importlib._bootstrap_external>", line 850, in exec_module
  File "<frozen importlib._bootstrap>", line 228, in _call_with_frames_removed
  File "/Users/rafaelgarcia/Desktop/GitHub/data-alchemy-suite/backend/core/urls.py", line 40, in <module>
    path('api/', include('products.urls')),
  File "/Users/rafaelgarcia/Desktop/GitHub/data-alchemy-suite/.venv/lib/python3.9/site-packages/django/urls/conf.py", line 38, in include
    urlconf_module = import_module(urlconf_module)
  File "/Library/Developer/CommandLineTools/Library/Frameworks/Python3.framework/Versions/3.9/lib/python3.9/importlib/__init__.py", line 127, in import_module
    return _bootstrap._gcd_import(name[level:], package, level)
  File "<frozen importlib._bootstrap>", line 1030, in _gcd_import
  File "<frozen importlib._bootstrap>", line 1007, in _find_and_load
  File "<frozen importlib._bootstrap>", line 986, in _find_and_load_unlocked
  File "<frozen importlib._bootstrap>", line 680, in _load_unlocked
  File "<frozen importlib._bootstrap_external>", line 850, in exec_module
  File "<frozen importlib._bootstrap>", line 228, in _call_with_frames_removed
  File "/Users/rafaelgarcia/Desktop/GitHub/data-alchemy-suite/backend/products/urls.py", line 7, in <module>
    from .views.sku_check import SkuCheckAPIView
ModuleNotFoundError: No module named 'products.views.sku_check'; 'products.views' is not a package
Initializing accounts app with custom authentication backend
Performing system checks...

Initializing accounts app with custom authentication backend
